
  0%|                                                                                                                                                 | 0/10 [00:00<?, ?it/s]
  0%|                                                                                                                                                 | 0/10 [00:06<?, ?it/s]
Traceback (most recent call last):
  File "C:\Users\asus\miniconda3\envs\projectAI\Lib\site-packages\torchmetrics\metric.py", line 457, in wrapped_func
    update(*args, **kwargs)
  File "C:\Users\asus\miniconda3\envs\projectAI\Lib\site-packages\torchmetrics\classification\stat_scores.py", line 329, in update
    self._update_state(tp, fp, tn, fn)
  File "C:\Users\asus\miniconda3\envs\projectAI\Lib\site-packages\torchmetrics\classification\stat_scores.py", line 77, in _update_state
    self.tp += tp
RuntimeError: Expected all tensors to be on the same device, but found at least two devices, cuda:0 and cpu!
The above exception was the direct cause of the following exception:
Traceback (most recent call last):
  File "d:\AI\Skills\Paper\handsign_classification\main.py", line 38, in <module>
    results = train.train(epochs=10, train_dataloader = train_dataloader, test_dataloader = val_dataloader)
              ^^^^^^^^^^^^^^^^^^^^^^^^^^^^^^^^^^^^^^^^^^^^^^^^^^^^^^^^^^^^^^^^^^^^^^^^^^^^^^^^^^^^^^^^^^^^^
  File "d:\AI\Skills\Paper\handsign_classification\trainer\trainer.py", line 105, in train
    train_loss, train_acc = self.train_epoch(dataloader = train_dataloader, device = self.device)
                            ^^^^^^^^^^^^^^^^^^^^^^^^^^^^^^^^^^^^^^^^^^^^^^^^^^^^^^^^^^^^^^^^^^^^^
  File "d:\AI\Skills\Paper\handsign_classification\trainer\trainer.py", line 58, in train_epoch
    train_acc += Accuracy(y_pred_class, y).item()
                 ^^^^^^^^^^^^^^^^^^^^^^^^^
  File "C:\Users\asus\miniconda3\envs\projectAI\Lib\site-packages\torch\nn\modules\module.py", line 1501, in _call_impl
    return forward_call(*args, **kwargs)
           ^^^^^^^^^^^^^^^^^^^^^^^^^^^^^
  File "C:\Users\asus\miniconda3\envs\projectAI\Lib\site-packages\torchmetrics\metric.py", line 298, in forward
    self._forward_cache = self._forward_reduce_state_update(*args, **kwargs)
                          ^^^^^^^^^^^^^^^^^^^^^^^^^^^^^^^^^^^^^^^^^^^^^^^^^^
  File "C:\Users\asus\miniconda3\envs\projectAI\Lib\site-packages\torchmetrics\metric.py", line 367, in _forward_reduce_state_update
    self.update(*args, **kwargs)
  File "C:\Users\asus\miniconda3\envs\projectAI\Lib\site-packages\torchmetrics\metric.py", line 460, in wrapped_func
    raise RuntimeError(
RuntimeError: Encountered different devices in metric calculation (see stacktrace for details). This could be due to the metric class not being on the same device as input. Instead of `metric=MulticlassAccuracy(...)` try to do `metric=MulticlassAccuracy(...).to(device)` where device corresponds to the device of the input.